Workbook

Sheet Horas comprometidas activdad
B1: Horas Comprometidas por Actividad
B2: Proyecto: | D2: ANÁLISIS DE RECURSOS HÍDRICOS EN CUENCAS DE LA REGIÓN DE MAGALLANES Y DE LA ANTÁRTICA CHILENA
B3: Oferente: | D3: IDIEM, UNIVERSIDAD DE CHILE
B4: Fecha: | D4: =+TODAY() -> 45889
B6: Nº | D6: Actividad/Sub-actividad | F6: Profesionales | AA6: Total hh por | AC6: Observaciones
F7: P1 | G7: P2 | H7: P3 | I7: P4 | J7: P5 | K7: P6 | L7: P7 | M7: P8 | N7: P9 | O7: P10 | P7: P11 | Q7: P12 | R7: P13 | S7: P14 | T7: P15 | U7: P16 | V7: P17 | W7: P18 | X7: P19 | Y7: P20 | AA7: Actividad /Subactividad
B9: 1 | C9: 1. Recopilación de Antecedentes | F9: =SUM(F10:F13) -> 76 | G9: =SUM(G10:G13) -> 60 | H9: =SUM(H10:H13) -> 24 | I9: =SUM(I10:I13) -> 44 | J9: =SUM(J10:J13) -> 60 | K9: =SUM(K10:K12) -> 0 | L9: =SUM(L10:L12) -> 0 | M9: =SUM(M10:M12) -> 0 | N9: =SUM(N10:N12) -> 0 | O9: =SUM(O10:O12) -> 0 | P9: =SUM(P10:P12) -> 0 | Q9: =SUM(Q10:Q12) -> 0 | R9: =SUM(R10:R12) -> 0 | ... Z9: =SUM(Z10:Z12) -> 0 | AA9: =IF(OR(C9<>"",D9<>""),SUM(F9:Y9),"") -> 264
B10: =+B9+1 -> 2 | D10: 1.1 Levantamiento y sistematización de información física ecosistémica y social mediante fichas resumen. | F10: 16 | G10: 16 | H10: 0 | I10: 8 | J10: 16 | AA10: =IF(OR(C10<>"",D10<>""),SUM(F10:Y10),"") -> 56
B11: =+B10+1 -> 3 | D11: 1.2 Modelo Conceptual Preliminar | F11: 16 | G11: 16 | H11: 8 | I11: =2*4*1*1 -> 8 | J11: 16 | AA11: =IF(OR(C11<>"",D11<>""),SUM(F11:Y11),"") -> 64
B12: =+B11+1 -> 4 | D12: 1.3 Elaboración de Informe de Avance 1 | F12: 32 | G12: 16 | H12: 16 | I12: 16 | J12: 16 | AA12: =IF(OR(C12<>"",D12<>""),SUM(F12:Y12),"") -> 96
D13: 1.4 Actividad Difusión Etapa 1 | F13: 12 | G13: 12 | H13: 0 | I13: 12 | J13: 12 | AA13: =IF(OR(C13<>"",D13<>""),SUM(F13:Y13),"") -> 48
B14: =+B12+1 -> 5 | C14: 2. Campañas de prospección | F14: =+SUM(F15:F23) -> 188 | G14: =+SUM(G15:G23) -> 204 | H14: =+SUM(H15:H23) -> 56 | I14: =+SUM(I15:I23) -> 148 | J14: =+SUM(J15:J23) -> 236 | K14: =+SUM(K15:K22) -> 0 | L14: =+SUM(L15:L22) -> 0 | M14: =+SUM(M15:M22) -> 0 | N14: =+SUM(N15:N22) -> 0 | O14: =+SUM(O15:O22) -> 0 | P14: =+SUM(P15:P22) -> 0 | Q14: =+SUM(Q15:Q22) -> 0 | R14: =+SUM(R15:R22) -> 0 | ... Y14: =+SUM(Y15:Y22) -> 0 | AA14: =IF(OR(C14<>"",D14<>""),SUM(F14:Y14),"") -> 832
B15: =+B14+1 -> 6 | D15: 2.1 Planificación de campañas de prospección | F15: 16 | G15: 8 | H15: 8 | I15: 8 | J15: 24 | AA15: =IF(OR(C15<>"",D15<>""),SUM(F15:Y15),"") -> 64
B16: =+B15+1 -> 7 | D16: 2.2 Realización de aforos | F16: 8 | G16: 16 | H16: 8 | I16: 0 | J16: 8 | AA16: =IF(OR(C16<>"",D16<>""),SUM(F16:Y16),"") -> 40
B17: =+B16+1 -> 8 | D17: 2.3 Realización de Pruebas de bombeo | F17: 8 | G17: 16 | H17: 8 | I17: 0 | J17: 32 | AA17: =IF(OR(C17<>"",D17<>""),SUM(F17:Y17),"") -> 64
B18: =+B17+1 -> 9 | D18: 2.4 Toma de muestras de calidad de aguas e isotopía | F18: 8 | G18: 16 | H18: 8 | I18: 0 | J18: 16 | AA18: =IF(OR(C18<>"",D18<>""),SUM(F18:Y18),"") -> 48
B19: =+B18+1 -> 10 | D19: 2.5 Visitas de inspección a obras de infraestructura | F19: 16 | G19: 16 | H19: 8 | I19: 16 | J19: 16 | AA19: =IF(OR(C19<>"",D19<>""),SUM(F19:Y19),"") -> 72
B20: =+B19+1 -> 11 | D20: 2.6 Visita para validar modelo conceptual (6) | F20: =2*8*6 -> 96 | G20: 96 | H20: 0 | I20: 96 | J20: 96 | AA20: =IF(OR(C20<>"",D20<>""),SUM(F20:Y20),"") -> 384
B21: =+B20+1 -> 12 | D21: 2.7 Geofísica (350 TEM + 260 gravimetría) | F21: 8 | G21: 8 | H21: 8 | I21: 0 | J21: 16 | AA21: =IF(OR(C21<>"",D21<>""),SUM(F21:Y21),"") -> 40
B22: =+B21+1 -> 13 | D22: 2.8 Elaboración de Informe de Avance 2 | F22: 16 | G22: 16 | H22: 8 | I22: 16 | J22: 16 | AA22: =IF(OR(C22<>"",D22<>""),SUM(F22:Y22),"") -> 72
B23: =+B22+1 -> 14 | D23: 2.9 Actividad Difusión Etapa 2 | F23: 12 | G23: 12 | H23: 0 | I23: 12 | J23: 12 | AA23: =IF(OR(C23<>"",D23<>""),SUM(F23:Y23),"") -> 48
B24: =+B23+1 -> 15 | C24: 3. Procesamiento y análisis crítico de la información | F24: =+SUM(F25:F32) -> 140 | G24: =+SUM(G25:G32) -> 108 | H24: =+SUM(H25:H32) -> 128 | I24: =+SUM(I25:I32) -> 130 | J24: =+SUM(J25:J32) -> 116 | K24: =+SUM(K25:K31) -> 0 | L24: =+SUM(L25:L31) -> 0 | M24: =+SUM(M25:M31) -> 0 | N24: =+SUM(N25:N31) -> 0 | O24: =+SUM(O25:O31) -> 0 | P24: =+SUM(P25:P31) -> 0 | Q24: =+SUM(Q25:Q31) -> 0 | R24: =+SUM(R25:R31) -> 0 | ... Y24: =+SUM(Y25:Y31) -> 0 | AA24: =IF(OR(C24<>"",D24<>""),SUM(F24:Y24),"") -> 622
B25: =+B24+1 -> 16 | D25: 3.1 Elaboración de Caracterización física, social y ecosistémica | F25: 16 | G25: 8 | H25: 24 | I25: 6 | J25: 24 | AA25: =IF(OR(C25<>"",D25<>""),SUM(F25:Y25),"") -> 78
B26: =+B25+1 -> 17 | D26: 3.2 Elaboración de diagramas unifilares de la red la red hidrográfica y canales | F26: 16 | G26: 16 | H26: 16 | I26: 24 | J26: 8 | AA26: =IF(OR(C26<>"",D26<>""),SUM(F26:Y26),"") -> 80
B27: =+B26+1 -> 18 | D27: 3.3 Diagnosticar el estado actual de las cuencas de estudio | F27: 16 | G27: 16 | H27: 8 | I27: 16 | J27: 16 | AA27: =IF(OR(C27<>"",D27<>""),SUM(F27:Y27),"") -> 72
B28: =+B27+1 -> 19 | D28: 3.4 Calcular la Oferta y Demanda de agua en las cuencas de estudio | F28: 16 | G28: 16 | H28: 16 | I28: 16 | J28: 16 | AA28: =IF(OR(C28<>"",D28<>""),SUM(F28:Y28),"") -> 80
B29: =+B28+1 -> 20 | D29: 3.5 Calcular el Balance hídrico en las cuencas de Estudio. | F29: 16 | G29: 8 | H29: 8 | I29: 24 | J29: 16 | AA29: =IF(OR(C29<>"",D29<>""),SUM(F29:Y29),"") -> 72
B30: =+B29+1 -> 21 | D30: 3.6 Sistematización y análisis de la Información de Derechos de Aprovechamiento de Aguas | F30: 16 | G30: 8 | H30: 40 | I30: 16 | J30: 8 | AA30: =IF(OR(C30<>"",D30<>""),SUM(F30:Y30),"") -> 88
B31: =+B30+1 -> 22 | D31: 3.7 Elaboración de Informe de Avance 3 | F31: 32 | G31: 24 | H31: 16 | I31: 16 | J31: 16 | AA31: =IF(OR(C31<>"",D31<>""),SUM(F31:Y31),"") -> 104
B32: =+B31+1 -> 23 | D32: 3 8 Actividad Difusión Etapa 3 | F32: 12 | G32: 12 | H32: 0 | I32: 12 | J32: 12 | AA32: =IF(OR(C32<>"",D32<>""),SUM(F32:Y32),"") -> 48
B33: =+B32+1 -> 24 | C33: 4. Construcción de modelos hidrológicos | F33: =+SUM(F34:F38) -> 108 | G33: =+SUM(G34:G38) -> 76 | H33: =+SUM(H34:H38) -> 40 | I33: =+SUM(I34:I38) -> 382 | J33: =+SUM(J34:J38) -> 268 | K33: =+SUM(K34:K37) -> 0 | L33: =+SUM(L34:L37) -> 0 | M33: =+SUM(M34:M37) -> 0 | N33: =+SUM(N34:N37) -> 0 | O33: =+SUM(O34:O37) -> 0 | P33: =+SUM(P34:P37) -> 0 | Q33: =+SUM(Q34:Q37) -> 0 | R33: =+SUM(R34:R37) -> 0 | ... Y33: =+SUM(Y34:Y37) -> 0 | AA33: =IF(OR(C33<>"",D33<>""),SUM(F33:Y33),"") -> 874
B34: =+B33+1 -> 25 | D34: 4.4 Construir una base de datos de la información input de los modelos | F34: 16 | G34: 16 | H34: 8 | I34: 120 | J34: 120 | AA34: =IF(OR(C34<>"",D34<>""),SUM(F34:Y34),"") -> 280
B35: =+B34+1 -> 26 | D35: 4.2 Construir un Modelo hidrológico conceptual | F35: 24 | G35: 16 | H35: 8 | I35: 150 | J35: 80 | AA35: =IF(OR(C35<>"",D35<>""),SUM(F35:Y35),"") -> 278
B36: =+B35+1 -> 27 | D36: 4.3 Construir un modelo hidrológico numérico | F36: 24 | G36: 16 | H36: 8 | I36: 60 | J36: 40 | AA36: =IF(OR(C36<>"",D36<>""),SUM(F36:Y36),"") -> 148
B37: =+B36+1 -> 28 | D37: 4.4 Elaboración de Informe de Avance 4 | F37: 32 | G37: 16 | H37: 16 | I37: 40 | J37: 16 | AA37: =IF(OR(C37<>"",D37<>""),SUM(F37:Y37),"") -> 120
B38: =+B37+1 -> 29 | D38: 4.5 Actividad Difusión Etapa 4 | F38: 12 | G38: 12 | H38: 0 | I38: 12 | J38: 12 | AA38: =IF(OR(C38<>"",D38<>""),SUM(F38:Y38),"") -> 48
B39: =+B38+1 -> 30 | C39: 5 Conclusiones e informes de resultados | F39: =+SUM(F40:F43) -> 88 | G39: =+SUM(G40:G43) -> 52 | H39: =+SUM(H40:H43) -> 152 | I39: =+SUM(I40:I43) -> 56 | J39: =+SUM(J40:J43) -> 80 | K39: =+SUM(K40:K42) -> 0 | L39: =+SUM(L40:L42) -> 0 | M39: =+SUM(M40:M42) -> 0 | N39: =+SUM(N40:N42) -> 0 | O39: =+SUM(O40:O42) -> 0 | P39: =+SUM(P40:P42) -> 0 | Q39: =+SUM(Q40:Q42) -> 0 | R39: =+SUM(R40:R42) -> 0 | ... Y39: =+SUM(Y40:Y42) -> 0 | AA39: =IF(OR(C39<>"",D39<>""),SUM(F39:Y39),"") -> 428
B40: =+B39+1 -> 31 | D40: 5.1 Elaborar un set de recomendaciones y mejoras para aumentar la seguridad hídrica | F40: =3*2*2*2 -> 24 | G40: 16 | H40: 0 | I40: 0 | J40: =3*2*2*2 -> 24 | AA40: =IF(OR(C40<>"",D40<>""),SUM(F40:Y40),"") -> 64
B41: =+B40+1 -> 32 | D41: 5.2 Elaboración de cartografía mediante un Sistema de Información Geográfico (SIG) | F41: 16 | G41: 4 | H41: 120 | I41: 16 | J41: 16 | AA41: =IF(OR(C41<>"",D41<>""),SUM(F41:Y41),"") -> 172
B42: =+B41+1 -> 33 | D42: 5.3 Elaboración de informes finales de resultados | F42: 32 | G42: 16 | H42: 32 | I42: 24 | J42: 24 | AA42: =IF(OR(C42<>"",D42<>""),SUM(F42:Y42),"") -> 128
...

Sheet Horas comprometidas profesional
B1: Horas Comprometidas por Profesional
B2: Proyecto: | C2: ='Horas comprometidas activdad'!D2 -> ANÁLISIS DE RECURSOS HÍDRICOS EN CUENCAS DE LA REGIÓN DE MAGALLANES Y DE LA ANTÁRTICA CHILENA
B3: Oferente: | C3: =+'Horas comprometidas activdad'!D3 -> IDIEM, UNIVERSIDAD DE CHILE
B4: Fecha: | C4: =+'Horas comprometidas activdad'!D4 -> 45889
B6: Profesional | C6: Cargo | D6: Nombre | E6: Total hh Comprometidas | G6: Total hh | H6: Observaciones
E7: Este estudio | F7: Otros Proyectos
B9: P1 | C9: Jefe de Proyecto | D9: Marcelo Olivares | E9: =+'Horas comprometidas activdad'!F122/2 -> 600 | F9: 2000 | G9: =IF(C9<>"",SUM(E9:F9),"") -> 2600
B10: P2 | C10: Especialista en Recursos Hídricos | D10: Norberto Werner | E10: =+'Horas comprometidas activdad'!G122/2 -> 500 | F10: 2500 | G10: =IF(C10<>"",SUM(E10:F10),"") -> 3000
B11: P3 | C11: Especialista SIG | D11: Carlos Leon | E11: =+'Horas comprometidas activdad'!H122/2 -> 400 | F11: 500 | G11: =IF(C11<>"",SUM(E11:F11),"") -> 900
B12: P4 | C12: Especialista en Modelación de Recursos Hídricos | D12: Iván Fuentes | E12: =+'Horas comprometidas activdad'!I122/2 -> 760 | F12: 300 | G12: =IF(C12<>"",SUM(E12:F12),"") -> 1060
B13: P5 | C13: Especialista en Hidrogeología | D13: Carolina Guzmán | E13: =+'Horas comprometidas activdad'!J122/2 -> 760 | F13: 2300 | G13: =IF(C13<>"",SUM(E13:F13),"") -> 3060
B14: P6 | G14: =IF(C14<>"",SUM(F14:F14),"")
B15: P7 | G15: =IF(C15<>"",SUM(F15:F15),"")
B16: P8 | G16: =IF(C16<>"",SUM(F16:F16),"")
B17: P9 | G17: =IF(C17<>"",SUM(F17:F17),"")
B18: P10 | G18: =IF(C18<>"",SUM(F18:F18),"")
B19: P11 | G19: =IF(C19<>"",SUM(F19:F19),"")
B20: P12 | G20: =IF(C20<>"",SUM(F20:F20),"")
B21: P13
B22: P14
B23: P15 | G23: =IF(C23<>"",SUM(F23:F23),"")
B24: P16 | G24: =IF(C24<>"",SUM(F24:F24),"")
B25: P17 | G25: =IF(C25<>"",SUM(F25:F25),"")
B26: P18 | G26: =IF(C26<>"",SUM(F26:F26),"")
B27: P19 | G27: =IF(C27<>"",SUM(F27:F27),"")
B28: P20 | G28: =IF(C28<>"",SUM(F28:F28),"")
B29: Total | F29: =SUM(F9:F28) -> 7600 | G29: =SUM(G9:G28) -> 10620
